<?xml version="1.0"?>
<robot xmlns:xacro="http://www.ros.org/wiki/xacro" name="my_robot">

  <!--<link name="base_footprint">
   </link>

  <joint name="base_footprint_joint" type="fixed">
     <parent link="base_footprint"/>
     <child link="base_link"/>
     <origin xyz="0.00 0.00 0.1" rpy="0.0 0.0 0.0"/>
   </joint>-->

  <link name="base_link">
  <inertial>
    <origin xyz="0 0 0.125" />
    <mass value="50" />
    <inertia  ixx="1.1" ixy="1.0"  ixz="0.0"  iyy="0.1"  iyz="0.0"  izz="0.1" />
  </inertial>
  <visual>
    <origin xyz="0 0 0.17"/>
    <geometry>
      <box size="0.8 0.545 0.17" />
    </geometry>
  </visual>
  <collision>
    <origin xyz="0 0 0.17"/>
    <geometry>
      <box size="0.8 0.545 0.17" />
    </geometry>
  </collision>
  </link>



  <gazebo reference="base_link">
    <material>Gazebo/DarkGrey</material>
  </gazebo>

  <link name="right_wheel">
  <inertial>
    <origin rpy="1.5707963267948966 0 0" xyz="0 0 0" />
    <mass value="1.1" />
    <inertia  ixx="1.01" ixy="0.0"  ixz="0.0"  iyy="1.01"  iyz="0.0"  izz="1.01" />
  </inertial>
  <visual>
    <origin rpy="1.5707963267948966 0 0" xyz="0 0 0"/>
    <geometry>
      <cylinder length="0.05" radius="0.12"/>
    </geometry>
  </visual>
  <collision>
    <origin rpy="1.5707963267948966 0 0" xyz="0 0 0"/>
    <geometry>
      <cylinder length="0.05" radius="0.12"/>
    </geometry>
  </collision>
  </link>

  

  <joint name="base_link_right_wheel" type="continuous">
    <parent link="base_link"/>
    <child link="right_wheel"/>
    <axis xyz="0 1 0"/>
    <origin xyz="0.3 -0.3 0.075"/>
  </joint>

  <transmission name="T_base_link_right_wheel">
    <type>transmission_interface/SimpleTransmission</type>
    <actuator name="motor_1">
      <mechanicalReduction>1</mechanicalReduction>
      <hardwareInterface>hardware_interface/VelocityJointInterface</hardwareInterface>
    </actuator>
    <joint name="base_link_right_wheel">
      <hardwareInterface>hardware_interface/VelocityJointInterface</hardwareInterface>
    </joint>
  </transmission>

  <link name="left_wheel">
  <inertial>
    <origin rpy="1.5707963267948966 0 0" xyz="0 0 0" />
    <mass value="1.1" />
    <inertia  ixx="1.01" ixy="0.0"  ixz="0.0"  iyy="1.01"  iyz="0.0"  izz="1.01" />
  </inertial>
  <visual>
    <origin rpy="1.5707963267948966 0 0" xyz="0 0 0"/>
    <geometry>
      <cylinder length="0.05" radius="0.12"/>
    </geometry>
  </visual>
  <collision>
    <origin rpy="1.5707963267948966 0 0" xyz="0 0 0"/>
    <geometry>
      <cylinder length="0.05" radius="0.12"/>
    </geometry>
  </collision>
  </link>

  <gazebo reference="left_wheel">
    <material>Gazebo/Black</material>
  </gazebo>

  <joint name="base_link_left_wheel" type="continuous">
    <parent link="base_link"/>
    <child link="left_wheel"/>
    <axis xyz="0 1 0"/>
    <origin xyz="0.3 0.3 0.075"/>
  </joint>

  <transmission name="T_base_link_left_wheel">
    <type>transmission_interface/SimpleTransmission</type>
    <actuator name="motor_2">
      <mechanicalReduction>1</mechanicalReduction>
      <hardwareInterface>hardware_interface/VelocityJointInterface</hardwareInterface>
    </actuator>
    <joint name="base_link_left_wheel">
      <hardwareInterface>hardware_interface/VelocityJointInterface</hardwareInterface>
    </joint>
  </transmission>

 

  <link name="right_back_wheel">
  <inertial>
    <origin rpy="1.5707963267948966 0 0" xyz="0 0 0" />
    <mass value="1.1" />
    <inertia  ixx="1.01" ixy="0.0"  ixz="0.0"  iyy="1.01"  iyz="0.0"  izz="1.01" />
  </inertial>
  <visual>
    <origin rpy="1.5707963267948966 0 0" xyz="0 0 0"/>
    <geometry>
      <cylinder length="0.05" radius="0.12"/>
    </geometry>
  </visual>
  <collision>
    <origin rpy="1.5707963267948966 0 0" xyz="0 0 0"/>
    <geometry>
      <cylinder length="0.05" radius="0.12"/>
    </geometry>
  </collision>
  </link>

<link name="camera_link">
    <collision>
      <origin xyz="0 0 0" rpy="0 0 0"/>
      <geometry>
    <box size="0.01 0.01 0.01"/>
      </geometry>
    </collision>

    <visual>
      <origin xyz="0 0 0" rpy="0 0 0"/>
      <geometry>
    <box size="0.01 0.01 0.01"/>
      </geometry>
      <material name="red"/>
    </visual>

    <inertial>
      <mass value="1e-5" />
      <origin xyz="0 0 0" rpy="0 0 0"/>
      <inertia ixx="1e-6" ixy="0" ixz="0" iyy="1e-6" iyz="0" izz="1e-6" />
    </inertial>
  </link>


  <joint name="camera_joint" type="fixed">
    <axis xyz="0 1 0" />
    <origin xyz="0.4 0.0 0.2" rpy="0 0 0"/>
    <parent link="base_link"/>
    <child link="camera_link"/>
  </joint>

   

  

  <joint name="base_link_right_back_wheel" type="continuous">
    <parent link="base_link"/>
    <child link="right_back_wheel"/>
    <axis xyz="0 1 0"/>
    <origin xyz="-0.3 -0.3 0.075"/>
  </joint>

  <transmission name="T_base_link_right_back_wheel">
    <type>transmission_interface/SimpleTransmission</type>
    <actuator name="motor_3">
      <mechanicalReduction>1</mechanicalReduction>
      <hardwareInterface>hardware_interface/VelocityJointInterface</hardwareInterface>
    </actuator>
    <joint name="base_link_right_back_wheel">
      <hardwareInterface>hardware_interface/VelocityJointInterface</hardwareInterface>
    </joint>
  </transmission>

  <link name="left_back_wheel">
  <inertial>
    <origin rpy="1.5707963267948966 0 0" xyz="0 0 0" />
    <mass value="1.1" />
    <inertia  ixx="1.01" ixy="0.0"  ixz="0.0"  iyy="1.01"  iyz="0.0"  izz="1.01" />
  </inertial>
  <visual>
    <origin rpy="1.5707963267948966 0 0" xyz="0 0 0"/>
    <geometry>
      <cylinder length="0.05" radius="0.12"/>
    </geometry>
  </visual>
  <collision>
    <origin rpy="1.5707963267948966 0 0" xyz="0 0 0"/>
    <geometry>
      <cylinder length="0.05" radius="0.12"/>
    </geometry>
  </collision>
  </link>

  

  <joint name="base_link_left_back_wheel" type="continuous">
    <parent link="base_link"/>
    <child link="left_back_wheel"/>
    <axis xyz="0 1 0"/>
    <origin xyz="-0.3 0.3 0.075"/>
  </joint>



  <transmission name="T_base_link_left_back_wheel">
    <type>transmission_interface/SimpleTransmission</type>
    <actuator name="motor_4">
      <mechanicalReduction>1</mechanicalReduction>
      <hardwareInterface>hardware_interface/VelocityJointInterface</hardwareInterface>
    </actuator>
    <joint name="base_link_left_back_wheel">
      <hardwareInterface>hardware_interface/VelocityJointInterface</hardwareInterface>
    </joint>
  </transmission>
<!-- gazebo properties -->
<gazebo reference="right_wheel">
    <material>Gazebo/Black</material>
<mu1>0.5</mu1>
    <mu2>0.5</mu2>
  </gazebo>

<gazebo reference="left_back_wheel">
    <material>Gazebo/Black</material>
<mu1>0.8</mu1>
    <mu2>0.8</mu2>
  </gazebo>
<gazebo reference="left_wheel">
    <material>Gazebo/Black</material>
<mu1>0.5</mu1>
    <mu2>0.5</mu2>
  </gazebo>

<gazebo reference="right_back_wheel">
    <material>Gazebo/Black</material>
    <mu1>0.8</mu1>
    <mu2>0.8</mu2>
  </gazebo>

<gazebo>
    <plugin name="skid_steer_drive_controller" filename="libgazebo_ros_skid_steer_drive.so">
        <alwaysOn>true</alwaysOn>
        <updateRate>100.0</updateRate>
        <leftFrontJoint>base_link_left_wheel</leftFrontJoint>
        <rightFrontJoint>base_link_right_wheel</rightFrontJoint>
        <leftRearJoint>base_link_left_back_wheel</leftRearJoint>
        <rightRearJoint>base_link_right_back_wheel</rightRearJoint>
        <wheelSeparation>0.545</wheelSeparation>
        <wheelDiameter>0.24</wheelDiameter>
        <torque>30</torque>
        <commandTopic>cmd_vel</commandTopic>
        <robotBaseFrame>base_link</robotBaseFrame>
        <broadcastTF>1</broadcastTF>
    </plugin>
</gazebo>


<!-- front camera -->
  <gazebo reference="camera_link">
    <sensor type="camera" name="camera">
      <update_rate>30.0</update_rate>
      <camera name="head">
        <horizontal_fov>2.2</horizontal_fov>
        <image>
          <width>640</width>
          <height>480</height>
          <format>R8G8B8</format>
        </image>
        <clip>
          <near>0.02</near>
          <far>300</far>
        </clip>
        <noise>
          <type>gaussian</type>
          <!-- Noise is sampled independently per pixel on each frame.
               That pixel's noise value is added to each of its color
               channels, which at that point lie in the range [0,1]. -->
          <mean>0.0</mean>
          <stddev>0.007</stddev>
        </noise>
      </camera>
      <plugin name="camera_controller" filename="libgazebo_ros_camera.so">
        <alwaysOn>true</alwaysOn>
        <updateRate>0.0</updateRate>
        <cameraName>/camera</cameraName>
        <imageTopicName>image_raw</imageTopicName>
        <cameraInfoTopicName>camera_info</cameraInfoTopicName>
        <frameName>camera_link1</frameName>
        <hackBaseline>0.07</hackBaseline>
        <distortionK1>0.0</distortionK1>
        <distortionK2>0.0</distortionK2>
        <distortionK3>0.0</distortionK3>
        <distortionT1>0.0</distortionT1>
        <distortionT2>0.0</distortionT2>
      </plugin>
    </sensor>
  </gazebo>


   
  <xacro:property name="camera_link" value="0.05" /> <!-- Size of square 'camera' box -->


 
</robot>
